<?xml version="1.0" ?>
<!-- =================================================================================== -->
<!-- |    This document was autogenerated by xacro from unipi_robot.urdf.xacro         | -->
<!-- |    EDITING THIS FILE BY HAND IS NOT RECOMMENDED                                 | -->
<!-- =================================================================================== -->
<robot name="unipi_robot" xmlns:controller="http://playerstage.sourceforge.net/gazebo/xmlschema/#controller" xmlns:interface="http://playerstage.sourceforge.net/gazebo/xmlschema/#interface" xmlns:sensor="http://playerstage.sourceforge.net/gazebo/xmlschema/#sensor" xmlns:xacro="http://ros.org/wiki/xacro">
  <material name="DarkGrey">
    <color rgba="0.3 0.3 0.3 1.0"/>
  </material>
  <material name="LightGrey">
    <color rgba="0.8 0.8 0.8 1.0"/>
  </material>
  <material name="Red">
    <color rgba="0.3 0.3 0.3 1.0"/>
  </material>
  <material name="Black">
    <color rgba="0 0 0 1.0"/>
  </material>
  <material name="Orange">
    <color rgba="1.0 0.487 0 1.0"/>
  </material>
  <material name="Silver">
    <color rgba="1.0 1.0 1.0 1.0"/>
  </material>
  <material name="Grey">
    <color rgba="0.7 0.7 0.7 1.0"/>
  </material>
  <material name="Blue">
    <color rgba="0.0 0.0 0.8 1.0"/>
  </material>
  <material name="HandGray">
    <color rgba="0.953 0.996 0.694 1.0"/>
  </material>
  <material name="SickBlue">
    <color rgba="0.3058 0.5921 0.7294 1.0"/>
  </material>
  <material name="DLR/LightGrey">
    <color rgba="0.7 0.7 0.7 1.0"/>
  </material>
  <material name="DLR/DarkGrey">
    <color rgba="0.4 0.4 0.4 1.0"/>
  </material>
  <material name="DLR/Black">
    <color rgba="0.0 0.0 0.0 1.0"/>
  </material>
  <material name="DLR/DarkGolden">
    <color rgba="0.4 0.4 0.3 1.0"/>
  </material>
  <material name="DLR/Blue">
    <color rgba="0.0 0.0 0.8 1.0"/>
  </material>
  <link name="world_link"/>
  <!--   <xacro:model_table name="table" 
                    parent="world"
                    length="1.45"
                    width="1"
                    height="0.9"
                    plate_thickness="0.1">
    <origin xyz="-1.22 0.5 0" rpy="0 0 0"/>
  </xacro:model_table> -->
  <joint name="world_torso_base_joint" type="fixed">
    <origin xyz="0 0 0"/>
    <parent link="world_link"/>
    <child link="torso_link"/>
  </joint>
  <link name="torso_link">
<!--     <visual>
      <geometry>
        <mesh filename="package://torso_unipi/meshes/torso.stl"/>
      </geometry>
      <material name="Silver"/>
    </visual>
    <collision>
      <geometry>
        <mesh filename="package://torso_unipi/meshes/torso.stl"/>
      </geometry>
    </collision> -->
  </link>
  <!--   <xacro:kuka_lwr_arm parent="world" name="left" right="1">
    <origin xyz="0.0 -0.108585 0.475" 
      rpy="${M_PI*40.8933907/180} ${M_PI*48.5903708/180} ${M_PI*-40.8933907/180}"/>
  </xacro:kuka_lwr_arm> -->
  <joint name="world_right_arm_base_joint" type="fixed">
    <origin rpy="-0.713724310019 0.848061955225 0.713724310019" xyz="0.0 0.108585 0.475"/>
    <origin rpy="0 0 0" xyz="0 0 0"/>
    <parent link="world_link"/>
    <child link="calib_right_arm_base_link"/>
  </joint>
  <link name="calib_right_arm_base_link">
    <inertial>
      <mass value="2.0"/>
      <origin xyz="0 0 0.055"/>
      <inertia ixx="0.00381666666667" ixy="0" ixz="0" iyy="0.0036" iyz="0" izz="0.00381666666667"/>
    </inertial>
    <visual>
      <origin rpy="0 0 3.14159265359" xyz="0 0 0"/>
      <geometry>
        <mesh filename="package://lwr_description/meshes/lwr/base.STL"/>
      </geometry>
      <material name="Orange"/>
    </visual>
    <collision>
      <origin rpy="0 0 3.14159265359" xyz="0 0 0.055"/>
      <geometry>
        <!--          <mesh filename="package://lwr_description/meshes/lwr/convex/arm_base_convex.stl"/> -->
        <cylinder length="0.11" radius="0.07"/>
      </geometry>
    </collision>
  </link>
  <joint name="right_arm_0_joint" type="revolute">
    <origin rpy="0 0 0" xyz="0 0 0.11"/>
    <axis xyz="0 0 1"/>
    <limit effort="204" lower="-2.96705972839" upper="2.96705972839" velocity="1.91986217719"/>
    <safety_controller k_position="30" k_velocity="30" soft_lower_limit="-2.93215314335" soft_upper_limit="2.93215314335"/>
    <dynamics damping="1.0"/>
    <parent link="calib_right_arm_base_link"/>
    <child link="right_arm_1_link"/>
  </joint>
  <link name="right_arm_1_link">
    <inertial>
      <mass value="2.0"/>
      <origin rpy="0 0 0" xyz="0 -0.06 0.130"/>
      <inertia ixx="0.0136666666667" ixy="0" ixz="0" iyy="0.003" iyz="0" izz="0.0118666666667"/>
    </inertial>
    <visual>
      <origin rpy="0 0 3.14159265359" xyz="0 0 -0.008"/>
      <geometry>
        <mesh filename="package://lwr_description/meshes/lwr/link_1.STL"/>
      </geometry>
      <material name="Orange"/>
    </visual>
    <!--
      <collision>
        <origin xyz="0 0 0" rpy="0 0 ${M_PI}"/>
        <geometry>
          <mesh filename="package://lwr_description/meshes/lwr/convex/arm_segment_a_convex.stl"/>
        </geometry>
      </collision>
 -->
    <collision>
      <origin rpy="0 0 0" xyz="0 0 0.0"/>
      <geometry>
        <sphere radius="0.07"/>
      </geometry>
    </collision>
    <collision>
      <origin rpy="0 0 0" xyz="0 0.06 0.2"/>
      <geometry>
        <sphere radius="0.07"/>
      </geometry>
    </collision>
    <collision>
      <origin rpy="-0.291 0 0" xyz="0 0.03 0.1"/>
      <geometry>
        <cylinder length="0.208" radius="0.07"/>
      </geometry>
    </collision>
  </link>
  <gazebo reference="right_arm_1_link">
    <gravity>false</gravity>
  </gazebo>
  <transmission name="right_arm_0_trans" type="SimpleTransmission">
    <actuator name="right_arm_0_motor"/>
    <joint name="right_arm_0_joint"/>
    <mechanicalReduction>1.0</mechanicalReduction>
  </transmission>
  <joint name="right_arm_1_joint" type="revolute">
    <origin rpy="0 0 0" xyz="0 0 0.2005"/>
    <axis xyz="0 -1 0"/>
    <limit effort="306" lower="-2.09439510239" upper="2.09439510239" velocity="1.91986217719"/>
    <safety_controller k_position="30" k_velocity="30" soft_lower_limit="-2.05948851735" soft_upper_limit="2.05948851735"/>
    <dynamics damping="1.0" friction="10"/>
    <parent link="right_arm_1_link"/>
    <child link="right_arm_2_link"/>
  </joint>
  <link name="right_arm_2_link">
    <inertial>
      <mass value="2.0"/>
      <origin rpy="0 0 0" xyz="0 0.06 0.07"/>
      <inertia ixx="0.0136666666667" ixy="0" ixz="0" iyy="0.003" iyz="0" izz="0.0118666666667"/>
    </inertial>
    <visual>
      <origin rpy="0 0 3.14159265359" xyz="0 0 0.0"/>
      <geometry>
        <mesh filename="package://lwr_description/meshes/lwr/link_2.STL"/>
      </geometry>
      <material name="Orange"/>
    </visual>
    <!--
      <collision>
        <origin xyz="0 0 0.2" rpy="${M_PI} 0 ${M_PI}"/>
        <geometry>
          <mesh filename="package://lwr_description/meshes/lwr/convex/arm_segment_b_convex.stl"/>
        </geometry>
      </collision>
-->
    <collision>
      <origin rpy="0 0 0" xyz="0 0 0.2"/>
      <geometry>
        <sphere radius="0.07"/>
      </geometry>
    </collision>
    <collision>
      <origin rpy="0 0 0" xyz="0 -0.06 0.0"/>
      <geometry>
        <sphere radius="0.07"/>
      </geometry>
    </collision>
    <collision>
      <origin rpy="-0.291 0 0" xyz="0 -0.03 0.1"/>
      <geometry>
        <cylinder length="0.208" radius="0.07"/>
      </geometry>
    </collision>
  </link>
  <gazebo reference="right_arm_2_link">
    <gravity>false</gravity>
  </gazebo>
  <transmission name="right_arm_1_trans" type="SimpleTransmission">
    <actuator name="right_arm_1_motor"/>
    <joint name="right_arm_1_joint"/>
    <mechanicalReduction>1.0</mechanicalReduction>
  </transmission>
  <joint name="right_arm_2_joint" type="revolute">
    <origin rpy="0 0 0" xyz="0 0 0.20"/>
    <axis xyz="0 0 1"/>
    <limit effort="204" lower="-2.96705972839" upper="2.96705972839" velocity="2.26892802759"/>
    <safety_controller k_position="30" k_velocity="30" soft_lower_limit="-2.93215314335" soft_upper_limit="2.93215314335"/>
    <dynamics damping="1.0"/>
    <parent link="right_arm_2_link"/>
    <child link="right_arm_3_link"/>
  </joint>
  <link name="right_arm_3_link">
    <inertial>
      <mass value="2.0"/>
      <origin rpy="0 0 0" xyz="0 0.06 0.130"/>
      <inertia ixx="0.0136666666667" ixy="0" ixz="0" iyy="0.003" iyz="0" izz="0.0118666666667"/>
    </inertial>
    <visual>
      <origin rpy="0 0 3.14159265359" xyz="0 0 -0.008"/>
      <geometry>
        <mesh filename="package://lwr_description/meshes/lwr/link_3.STL"/>
      </geometry>
      <material name="Orange"/>
    </visual>
    <!--
      <collision>
        <origin xyz="0 0 0" rpy="0 0 ${M_PI}"/>
        <geometry>
          <mesh filename="package://lwr_description/meshes/lwr/convex/arm_segment_a_convex.stl"/>
        </geometry>
      </collision>
-->
    <collision>
      <origin rpy="0 0 0" xyz="0 0 0.0"/>
      <geometry>
        <sphere radius="0.07"/>
      </geometry>
    </collision>
    <collision>
      <origin rpy="0 0 0" xyz="0 -0.06 0.2"/>
      <geometry>
        <sphere radius="0.07"/>
      </geometry>
    </collision>
    <collision>
      <origin rpy="0.291 0 0" xyz="0 -0.03 0.1"/>
      <geometry>
        <cylinder length="0.208" radius="0.07"/>
      </geometry>
    </collision>
  </link>
  <gazebo reference="right_arm_3_link">
    <gravity>false</gravity>
  </gazebo>
  <transmission name="right_arm_2_trans" type="SimpleTransmission">
    <actuator name="right_arm_2_motor"/>
    <joint name="right_arm_2_joint"/>
    <mechanicalReduction>1.0</mechanicalReduction>
  </transmission>
  <joint name="right_arm_3_joint" type="revolute">
    <origin rpy="0 0 0" xyz="0 0 0.20"/>
    <axis xyz="0 1 0"/>
    <limit effort="306" lower="-2.09439510239" upper="2.09439510239" velocity="2.26892802759"/>
    <safety_controller k_position="30" k_velocity="30" soft_lower_limit="-2.05948851735" soft_upper_limit="2.05948851735"/>
    <dynamics damping="1.0"/>
    <parent link="right_arm_3_link"/>
    <child link="right_arm_4_link"/>
  </joint>
  <link name="right_arm_4_link">
    <inertial>
      <mass value="2.0"/>
      <origin rpy="0 0 0" xyz="0 -0.06 0.07"/>
      <inertia ixx="0.0136666666667" ixy="0" ixz="0" iyy="0.003" iyz="0" izz="0.0118666666667"/>
    </inertial>
    <visual>
      <origin rpy="0 0 3.14159265359" xyz="0 0 0.0"/>
      <geometry>
        <mesh filename="package://lwr_description/meshes/lwr/link_4.STL"/>
      </geometry>
      <material name="Orange"/>
    </visual>
    <!--
      <collision>
        <origin xyz="0 0 0.2" rpy="0 ${M_PI} 0"/>
        <geometry>
          <mesh filename="package://lwr_description/meshes/lwr/convex/arm_segment_b_convex.stl"/>
        </geometry>
      </collision>
-->
    <collision>
      <origin rpy="0 0 0" xyz="0 0 0.2"/>
      <geometry>
        <sphere radius="0.07"/>
      </geometry>
    </collision>
    <collision>
      <origin rpy="0 0 0" xyz="0 0.06 0.0"/>
      <geometry>
        <sphere radius="0.07"/>
      </geometry>
    </collision>
    <collision>
      <origin rpy="0.291 0 0" xyz="0 0.03 0.1"/>
      <geometry>
        <cylinder length="0.208" radius="0.07"/>
      </geometry>
    </collision>
  </link>
  <gazebo reference="right_arm_4_link">
    <gravity>false</gravity>
  </gazebo>
  <transmission name="right_arm_3_trans" type="SimpleTransmission">
    <actuator name="right_arm_3_motor"/>
    <joint name="right_arm_3_joint"/>
    <mechanicalReduction>1.0</mechanicalReduction>
  </transmission>
  <joint name="right_arm_4_joint" type="revolute">
    <origin rpy="0 0 0" xyz="0 0 0.20"/>
    <axis xyz="0 0 1"/>
    <limit effort="204" lower="-2.96705972839" upper="2.96705972839" velocity="2.26892802759"/>
    <safety_controller k_position="30" k_velocity="30" soft_lower_limit="-2.93215314335" soft_upper_limit="2.93215314335"/>
    <dynamics damping="1.0"/>
    <parent link="right_arm_4_link"/>
    <child link="right_arm_5_link"/>
  </joint>
  <link name="right_arm_5_link">
    <inertial>
      <mass value="2.0"/>
      <origin rpy="0 0 0" xyz="0 0 0.124"/>
      <inertia ixx="0.0126506666667" ixy="0" ixz="0" iyy="0.003" iyz="0" izz="0.0108506666667"/>
    </inertial>
    <visual>
      <origin rpy="0 0 3.14159265359" xyz="0 0 -0.008"/>
      <geometry name="right_arm_5_geom">
        <mesh filename="package://lwr_description/meshes/lwr/link_5.STL"/>
      </geometry>
      <material name="Orange"/>
    </visual>
    <!--
      <collision>
        <origin xyz="0 0 0" rpy="0 0 ${M_PI}"/>
        <geometry>
          <mesh filename="package://lwr_description/meshes/lwr/convex/arm_segment_last_convex.stl"/>
        </geometry>
      </collision>
-->
    <collision>
      <origin rpy="0 0 0" xyz="0 0 0.0"/>
      <geometry>
        <sphere radius="0.07"/>
      </geometry>
    </collision>
    <collision>
      <origin rpy="0 0 0" xyz="0 0.04 0.19"/>
      <geometry>
        <sphere radius="0.07"/>
      </geometry>
    </collision>
    <collision>
      <origin rpy="-0.207 0 0" xyz="0 0.02 0.095"/>
      <geometry>
        <cylinder length="0.198" radius="0.07"/>
      </geometry>
    </collision>
  </link>
  <gazebo reference="right_arm_5_link">
    <gravity>false</gravity>
  </gazebo>
  <transmission name="right_arm_4_trans" type="SimpleTransmission">
    <actuator name="right_arm_4_motor"/>
    <joint name="right_arm_4_joint"/>
    <mechanicalReduction>1.0</mechanicalReduction>
  </transmission>
  <joint name="right_arm_5_joint" type="revolute">
    <origin rpy="0 0 0" xyz="0 0 0.19"/>
    <axis xyz="0 -1 0"/>
    <limit effort="306" lower="-2.09439510239" upper="2.09439510239" velocity="3.14159265359"/>
    <safety_controller k_position="30" k_velocity="30" soft_lower_limit="-2.05948851735" soft_upper_limit="2.05948851735"/>
    <dynamics damping="1.0"/>
    <parent link="right_arm_5_link"/>
    <child link="right_arm_6_link"/>
  </joint>
  <link name="right_arm_6_link">
    <inertial>
      <mass value="0.2"/>
      <origin rpy="0 0 0" xyz="0 0 0.0625"/>
      <inertia ixx="0.000520833333333" ixy="0" ixz="0" iyy="0.000520833333333" iyz="0" izz="0.000520833333333"/>
    </inertial>
    <visual>
      <origin rpy="0 0 3.14159265359" xyz="0 0 0"/>
      <geometry>
        <mesh filename="package://lwr_description/meshes/lwr/link_6.STL"/>
      </geometry>
      <material name="Grey"/>
    </visual>
    <collision>
      <origin rpy="0 0 3.14159265359" xyz="0 0 0"/>
      <geometry>
        <mesh filename="package://lwr_description/meshes/lwr/convex/arm_wrist_convex.stl"/>
      </geometry>
    </collision>
  </link>
  <gazebo reference="right_arm_6_link">
    <gravity>false</gravity>
  </gazebo>
  <transmission name="right_arm_5_trans" type="SimpleTransmission">
    <actuator name="right_arm_5_motor"/>
    <joint name="right_arm_5_joint"/>
    <mechanicalReduction>1.0</mechanicalReduction>
  </transmission>
  <joint name="right_arm_6_joint" type="revolute">
    <origin rpy="0 0 0" xyz="0 0 0.078"/>
    <axis xyz="0 0 1"/>
    <limit effort="204" lower="-2.96705972839" upper="2.96705972839" velocity="3.14159265359"/>
    <safety_controller k_position="30" k_velocity="30" soft_lower_limit="-2.93215314335" soft_upper_limit="2.93215314335"/>
    <dynamics damping="1.0"/>
    <parent link="right_arm_6_link"/>
    <child link="right_arm_7_link"/>
  </joint>
  <link name="right_arm_7_link">
    <inertial>
      <mass value="0.2"/>
      <origin xyz="0 0 0"/>
      <inertia ixx="0.0333333333333" ixy="0" ixz="0" iyy="0.0333333333333" iyz="0" izz="0.0333333333333"/>
    </inertial>
    <visual>
      <origin rpy="0 0 3.14159265359" xyz="0 0 0"/>
      <geometry>
        <mesh filename="package://lwr_description/meshes/lwr/link_7.STL"/>
      </geometry>
      <material name="DarkGrey"/>
    </visual>
    <collision>
      <origin rpy="0 0 3.14159265359" xyz="0 0 0"/>
      <geometry>
        <cylinder length="0.05" radius="0.04"/>
      </geometry>
    </collision>
  </link>
  <gazebo reference="right_arm_7_link">
    <gravity>false</gravity>
  </gazebo>
  <transmission name="right_arm_6_trans" type="SimpleTransmission">
    <actuator name="right_arm_6_motor"/>
    <joint name="right_arm_6_joint"/>
    <mechanicalReduction>1.0</mechanicalReduction>
  </transmission>
  <!--   <xacro:stewart_wrist name="stewart_wrist" parent="left_arm_7_link"  color="Orange">
    <origin xyz="0 0 0"
      rpy="0 0 0"/>
  </xacro:stewart_wrist> -->
  <joint name="right_palm_joint" type="fixed">
    <origin rpy="0 0 0" xyz="0 0 0"/>
    <parent link="right_arm_7_link"/>
    <child link="right_palm_link"/>
  </joint>
  <link name="right_palm_link">
    <inertial>
      <!-- PALM MASS AND INERTIA TO BE ESTIMATED!!!! -->
      <origin rpy="0 0 0" xyz="0 0 0"/>
      <mass value="1"/>
      <inertia ixx="0.01" ixy="0" ixz="0" iyy="0.01" iyz="0" izz="0.01"/>
    </inertial>
    <!-- also check whether is ok to leave at zero the origin -->
    <visual>
      <origin rpy="0 0 0" xyz="0 0 0"/>
      <geometry>
        <mesh filename="package://dlr_description/meshes/hit2/palm.stl"/>
      </geometry>
      <material name="DLR/LightGrey"/>
    </visual>
    <collision>
      <origin rpy="0 0 0" xyz="0 0 0"/>
      <geometry>
        <mesh filename="package://dlr_description/meshes/hit2/palm.stl"/>
      </geometry>
    </collision>
  </link>
  <joint name="right_thumb_abd_joint" type="revolute">
    <origin rpy="0.41136 -1.08366 0.225804" xyz="0.062569057 0.044544548 0.080044647"/>
    <parent link="right_palm_link"/>
    <child link="right_thumb_abd_link"/>
    <axis xyz="0 0 1"/>
    <dynamics damping="1"/>
    <limit effort="100" lower="-0.349065850399" upper="0.349065850399" velocity="5"/>
    <!-- effort="100" velocity="5" -->
  </joint>
  <link name="right_thumb_abd_link">
    <inertial>
      <origin rpy="0 0 0" xyz="0 0 0"/>
      <mass value="0.0"/>
      <inertia ixx="0" ixy="0" ixz="0" iyy="0" iyz="0" izz="0"/>
    </inertial>
    <!-- possibly add basecover.stl as both geometry and collision... -->
    <visual>
      <origin rpy="0 0 0" xyz="0 0 0"/>
      <geometry>
        <mesh filename="package://dlr_description/meshes/hit2/base.stl"/>
      </geometry>
      <material name="DLR/LightGrey"/>
    </visual>
  </link>
  <joint name="right_thumb_inner_joint" type="revolute">
    <!-- coincident with abd_joint, rotated of 90 degrees along x -->
    <origin rpy="1.57079632679 0 0" xyz="0 0 0"/>
    <parent link="right_thumb_abd_link"/>
    <child link="right_thumb_proximal_link"/>
    <axis xyz="0 0 1"/>
    <dynamics damping="1"/>
    <limit effort="100" lower="0.0" upper="1.308996939" velocity="5"/>
    <!-- effort="100" velocity="5" -->
  </joint>
  <link name="right_thumb_proximal_link">
    <!-- <inertial>
      <origin rpy="0 0 0" xyz="30.164510e -1.0130813 0.50813186"/>
      <mass value="0.044370598"/>
      <inertia ixx="4.5592704e-06" ixy="9.0783105e-07" ixz="-9.399771e-07" iyy="4.9045259e-05" iyz="1.7052714e-08" izz="5.0524234e-05"/>
    </inertial> -->
    <visual>
      <origin rpy="0 0 0" xyz="0 0 0"/>
      <geometry>
        <mesh filename="package://dlr_description/meshes/hit2/proximal.stl"/>
      </geometry>
      <material name="DLR/LightGrey"/>
    </visual>
    <collision>
      <origin rpy="0 0 0" xyz="0 0 0"/>
      <geometry>
        <mesh filename="package://dlr_description/meshes/hit2/proximal.stl"/>
      </geometry>
    </collision>
  </link>
  <joint name="right_thumb_outer1_joint" type="revolute">
    <origin rpy="0 0 0" xyz="0.055 0 0"/>
    <parent link="right_thumb_proximal_link"/>
    <child link="right_thumb_medial_link"/>
    <axis xyz="0 0 1"/>
    <dynamics damping="1"/>
    <limit effort="100" lower="0.0" upper="1.308996939" velocity="5"/>
    <!-- effort="100" velocity="5" -->
  </joint>
  <link name="right_thumb_medial_link">
    <inertial>
      <origin rpy="0 0 0" xyz="5.7271879 -1.6164173 -1.1567914"/>
      <mass value="0.027110192"/>
      <inertia ixx="2.2900229e-06" ixy="4.0604622e-07" ixz="1.4362094e-07" iyy="4.2155489e-06" iyz="-4.3115648e-08" izz="4.4292927e-06"/>
    </inertial>
    <visual>
      <origin rpy="0 0 0" xyz="0 0 0"/>
      <geometry>
        <mesh filename="package://dlr_description/meshes/hit2/medial.stl"/>
      </geometry>
      <material name="DLR/LightGrey"/>
    </visual>
    <collision>
      <origin rpy="0 0 0" xyz="0 0 0"/>
      <geometry>
        <mesh filename="package://dlr_description/meshes/hit2/medial.stl"/>
      </geometry>
    </collision>
  </link>
  <joint name="right_thumb_outer2_joint" type="revolute">
    <origin rpy="0 0 -1.57079632679" xyz="0.025 0 0"/>
    <parent link="right_thumb_medial_link"/>
    <child link="right_thumb_distal_link"/>
    <axis xyz="0 0 1"/>
    <dynamics damping="1"/>
    <limit effort="100" lower="0.0" upper="1.308996939" velocity="5"/>
    <!-- effort="100" velocity="5" -->
  </joint>
  <link name="right_thumb_distal_link">
    <inertial>
      <origin rpy="0 0 0" xyz="-0.83348211 6.1007977 1.7728256"/>
      <mass value="0.018179709"/>
      <inertia ixx="2.5867271e-06" ixy="1.5840536e-07" ixz="-7.8205885e-10" iyy="8.4596248e-07" iyz="-4.8358115e-09" izz="2.5838485e-06"/>
    </inertial>
    <visual>
      <origin rpy="0 0 0" xyz="0 0 0"/>
      <geometry>
        <mesh filename="package://dlr_description/meshes/hit2/distal.stl"/>
      </geometry>
      <material name="DLR/LightGrey"/>
    </visual>
    <collision>
      <origin rpy="0 0 0" xyz="0 0 0"/>
      <geometry>
        <mesh filename="package://dlr_description/meshes/hit2/distal.stl"/>
      </geometry>
    </collision>
  </link>
  <joint name="right_index_abd_joint" type="revolute">
    <origin rpy="3.05433 -1.57079632679 0" xyz="-0.002529881 0.036800135 0.108743545"/>
    <parent link="right_palm_link"/>
    <child link="right_index_abd_link"/>
    <axis xyz="0 0 1"/>
    <dynamics damping="1"/>
    <limit effort="100" lower="-0.349065850399" upper="0.349065850399" velocity="5"/>
    <!-- effort="100" velocity="5" -->
  </joint>
  <link name="right_index_abd_link">
    <inertial>
      <origin rpy="0 0 0" xyz="0 0 0"/>
      <mass value="0.0"/>
      <inertia ixx="0" ixy="0" ixz="0" iyy="0" iyz="0" izz="0"/>
    </inertial>
    <!-- possibly add basecover.stl as both geometry and collision... -->
    <visual>
      <origin rpy="0 0 0" xyz="0 0 0"/>
      <geometry>
        <mesh filename="package://dlr_description/meshes/hit2/base.stl"/>
      </geometry>
      <material name="DLR/LightGrey"/>
    </visual>
  </link>
  <joint name="right_index_inner_joint" type="revolute">
    <!-- coincident with abd_joint, rotated of 90 degrees along x -->
    <origin rpy="1.57079632679 0 0" xyz="0 0 0"/>
    <parent link="right_index_abd_link"/>
    <child link="right_index_proximal_link"/>
    <axis xyz="0 0 1"/>
    <dynamics damping="1"/>
    <limit effort="100" lower="0.0" upper="1.308996939" velocity="5"/>
    <!-- effort="100" velocity="5" -->
  </joint>
  <link name="right_index_proximal_link">
    <!-- <inertial>
      <origin rpy="0 0 0" xyz="30.164510e -1.0130813 0.50813186"/>
      <mass value="0.044370598"/>
      <inertia ixx="4.5592704e-06" ixy="9.0783105e-07" ixz="-9.399771e-07" iyy="4.9045259e-05" iyz="1.7052714e-08" izz="5.0524234e-05"/>
    </inertial> -->
    <visual>
      <origin rpy="0 0 0" xyz="0 0 0"/>
      <geometry>
        <mesh filename="package://dlr_description/meshes/hit2/proximal.stl"/>
      </geometry>
      <material name="DLR/LightGrey"/>
    </visual>
    <collision>
      <origin rpy="0 0 0" xyz="0 0 0"/>
      <geometry>
        <mesh filename="package://dlr_description/meshes/hit2/proximal.stl"/>
      </geometry>
    </collision>
  </link>
  <joint name="right_index_outer1_joint" type="revolute">
    <origin rpy="0 0 0" xyz="0.055 0 0"/>
    <parent link="right_index_proximal_link"/>
    <child link="right_index_medial_link"/>
    <axis xyz="0 0 1"/>
    <dynamics damping="1"/>
    <limit effort="100" lower="0.0" upper="1.308996939" velocity="5"/>
    <!-- effort="100" velocity="5" -->
  </joint>
  <link name="right_index_medial_link">
    <inertial>
      <origin rpy="0 0 0" xyz="5.7271879 -1.6164173 -1.1567914"/>
      <mass value="0.027110192"/>
      <inertia ixx="2.2900229e-06" ixy="4.0604622e-07" ixz="1.4362094e-07" iyy="4.2155489e-06" iyz="-4.3115648e-08" izz="4.4292927e-06"/>
    </inertial>
    <visual>
      <origin rpy="0 0 0" xyz="0 0 0"/>
      <geometry>
        <mesh filename="package://dlr_description/meshes/hit2/medial.stl"/>
      </geometry>
      <material name="DLR/LightGrey"/>
    </visual>
    <collision>
      <origin rpy="0 0 0" xyz="0 0 0"/>
      <geometry>
        <mesh filename="package://dlr_description/meshes/hit2/medial.stl"/>
      </geometry>
    </collision>
  </link>
  <joint name="right_index_outer2_joint" type="revolute">
    <origin rpy="0 0 -1.57079632679" xyz="0.025 0 0"/>
    <parent link="right_index_medial_link"/>
    <child link="right_index_distal_link"/>
    <axis xyz="0 0 1"/>
    <dynamics damping="1"/>
    <limit effort="100" lower="0.0" upper="1.308996939" velocity="5"/>
    <!-- effort="100" velocity="5" -->
  </joint>
  <link name="right_index_distal_link">
    <inertial>
      <origin rpy="0 0 0" xyz="-0.83348211 6.1007977 1.7728256"/>
      <mass value="0.018179709"/>
      <inertia ixx="2.5867271e-06" ixy="1.5840536e-07" ixz="-7.8205885e-10" iyy="8.4596248e-07" iyz="-4.8358115e-09" izz="2.5838485e-06"/>
    </inertial>
    <visual>
      <origin rpy="0 0 0" xyz="0 0 0"/>
      <geometry>
        <mesh filename="package://dlr_description/meshes/hit2/distal.stl"/>
      </geometry>
      <material name="DLR/LightGrey"/>
    </visual>
    <collision>
      <origin rpy="0 0 0" xyz="0 0 0"/>
      <geometry>
        <mesh filename="package://dlr_description/meshes/hit2/distal.stl"/>
      </geometry>
    </collision>
  </link>
  <joint name="right_middle_abd_joint" type="revolute">
    <origin rpy="3.14159265359 -1.57079632679 0" xyz="-0.0037 0.01 0.119043545"/>
    <parent link="right_palm_link"/>
    <child link="right_middle_abd_link"/>
    <axis xyz="0 0 1"/>
    <dynamics damping="1"/>
    <limit effort="100" lower="-0.349065850399" upper="0.349065850399" velocity="5"/>
    <!-- effort="100" velocity="5" -->
  </joint>
  <link name="right_middle_abd_link">
    <inertial>
      <origin rpy="0 0 0" xyz="0 0 0"/>
      <mass value="0.0"/>
      <inertia ixx="0" ixy="0" ixz="0" iyy="0" iyz="0" izz="0"/>
    </inertial>
    <!-- possibly add basecover.stl as both geometry and collision... -->
    <visual>
      <origin rpy="0 0 0" xyz="0 0 0"/>
      <geometry>
        <mesh filename="package://dlr_description/meshes/hit2/base.stl"/>
      </geometry>
      <material name="DLR/LightGrey"/>
    </visual>
  </link>
  <joint name="right_middle_inner_joint" type="revolute">
    <!-- coincident with abd_joint, rotated of 90 degrees along x -->
    <origin rpy="1.57079632679 0 0" xyz="0 0 0"/>
    <parent link="right_middle_abd_link"/>
    <child link="right_middle_proximal_link"/>
    <axis xyz="0 0 1"/>
    <dynamics damping="1"/>
    <limit effort="100" lower="0.0" upper="1.308996939" velocity="5"/>
    <!-- effort="100" velocity="5" -->
  </joint>
  <link name="right_middle_proximal_link">
    <!-- <inertial>
      <origin rpy="0 0 0" xyz="30.164510e -1.0130813 0.50813186"/>
      <mass value="0.044370598"/>
      <inertia ixx="4.5592704e-06" ixy="9.0783105e-07" ixz="-9.399771e-07" iyy="4.9045259e-05" iyz="1.7052714e-08" izz="5.0524234e-05"/>
    </inertial> -->
    <visual>
      <origin rpy="0 0 0" xyz="0 0 0"/>
      <geometry>
        <mesh filename="package://dlr_description/meshes/hit2/proximal.stl"/>
      </geometry>
      <material name="DLR/LightGrey"/>
    </visual>
    <collision>
      <origin rpy="0 0 0" xyz="0 0 0"/>
      <geometry>
        <mesh filename="package://dlr_description/meshes/hit2/proximal.stl"/>
      </geometry>
    </collision>
  </link>
  <joint name="right_middle_outer1_joint" type="revolute">
    <origin rpy="0 0 0" xyz="0.055 0 0"/>
    <parent link="right_middle_proximal_link"/>
    <child link="right_middle_medial_link"/>
    <axis xyz="0 0 1"/>
    <dynamics damping="1"/>
    <limit effort="100" lower="0.0" upper="1.308996939" velocity="5"/>
    <!-- effort="100" velocity="5" -->
  </joint>
  <link name="right_middle_medial_link">
    <inertial>
      <origin rpy="0 0 0" xyz="5.7271879 -1.6164173 -1.1567914"/>
      <mass value="0.027110192"/>
      <inertia ixx="2.2900229e-06" ixy="4.0604622e-07" ixz="1.4362094e-07" iyy="4.2155489e-06" iyz="-4.3115648e-08" izz="4.4292927e-06"/>
    </inertial>
    <visual>
      <origin rpy="0 0 0" xyz="0 0 0"/>
      <geometry>
        <mesh filename="package://dlr_description/meshes/hit2/medial.stl"/>
      </geometry>
      <material name="DLR/LightGrey"/>
    </visual>
    <collision>
      <origin rpy="0 0 0" xyz="0 0 0"/>
      <geometry>
        <mesh filename="package://dlr_description/meshes/hit2/medial.stl"/>
      </geometry>
    </collision>
  </link>
  <joint name="right_middle_outer2_joint" type="revolute">
    <origin rpy="0 0 -1.57079632679" xyz="0.025 0 0"/>
    <parent link="right_middle_medial_link"/>
    <child link="right_middle_distal_link"/>
    <axis xyz="0 0 1"/>
    <dynamics damping="1"/>
    <limit effort="100" lower="0.0" upper="1.308996939" velocity="5"/>
    <!-- effort="100" velocity="5" -->
  </joint>
  <link name="right_middle_distal_link">
    <inertial>
      <origin rpy="0 0 0" xyz="-0.83348211 6.1007977 1.7728256"/>
      <mass value="0.018179709"/>
      <inertia ixx="2.5867271e-06" ixy="1.5840536e-07" ixz="-7.8205885e-10" iyy="8.4596248e-07" iyz="-4.8358115e-09" izz="2.5838485e-06"/>
    </inertial>
    <visual>
      <origin rpy="0 0 0" xyz="0 0 0"/>
      <geometry>
        <mesh filename="package://dlr_description/meshes/hit2/distal.stl"/>
      </geometry>
      <material name="DLR/LightGrey"/>
    </visual>
    <collision>
      <origin rpy="0 0 0" xyz="0 0 0"/>
      <geometry>
        <mesh filename="package://dlr_description/meshes/hit2/distal.stl"/>
      </geometry>
    </collision>
  </link>
  <joint name="right_ring_abd_joint" type="revolute">
    <origin rpy="-3.05433 -1.57079632679 0" xyz="-0.002529881 -0.016800135 0.114043545"/>
    <parent link="right_palm_link"/>
    <child link="right_ring_abd_link"/>
    <axis xyz="0 0 1"/>
    <dynamics damping="1"/>
    <limit effort="100" lower="-0.349065850399" upper="0.349065850399" velocity="5"/>
    <!-- effort="100" velocity="5" -->
  </joint>
  <link name="right_ring_abd_link">
    <inertial>
      <origin rpy="0 0 0" xyz="0 0 0"/>
      <mass value="0.0"/>
      <inertia ixx="0" ixy="0" ixz="0" iyy="0" iyz="0" izz="0"/>
    </inertial>
    <!-- possibly add basecover.stl as both geometry and collision... -->
    <visual>
      <origin rpy="0 0 0" xyz="0 0 0"/>
      <geometry>
        <mesh filename="package://dlr_description/meshes/hit2/base.stl"/>
      </geometry>
      <material name="DLR/LightGrey"/>
    </visual>
  </link>
  <joint name="right_ring_inner_joint" type="revolute">
    <!-- coincident with abd_joint, rotated of 90 degrees along x -->
    <origin rpy="1.57079632679 0 0" xyz="0 0 0"/>
    <parent link="right_ring_abd_link"/>
    <child link="right_ring_proximal_link"/>
    <axis xyz="0 0 1"/>
    <dynamics damping="1"/>
    <limit effort="100" lower="0.0" upper="1.308996939" velocity="5"/>
    <!-- effort="100" velocity="5" -->
  </joint>
  <link name="right_ring_proximal_link">
    <!-- <inertial>
      <origin rpy="0 0 0" xyz="30.164510e -1.0130813 0.50813186"/>
      <mass value="0.044370598"/>
      <inertia ixx="4.5592704e-06" ixy="9.0783105e-07" ixz="-9.399771e-07" iyy="4.9045259e-05" iyz="1.7052714e-08" izz="5.0524234e-05"/>
    </inertial> -->
    <visual>
      <origin rpy="0 0 0" xyz="0 0 0"/>
      <geometry>
        <mesh filename="package://dlr_description/meshes/hit2/proximal.stl"/>
      </geometry>
      <material name="DLR/LightGrey"/>
    </visual>
    <collision>
      <origin rpy="0 0 0" xyz="0 0 0"/>
      <geometry>
        <mesh filename="package://dlr_description/meshes/hit2/proximal.stl"/>
      </geometry>
    </collision>
  </link>
  <joint name="right_ring_outer1_joint" type="revolute">
    <origin rpy="0 0 0" xyz="0.055 0 0"/>
    <parent link="right_ring_proximal_link"/>
    <child link="right_ring_medial_link"/>
    <axis xyz="0 0 1"/>
    <dynamics damping="1"/>
    <limit effort="100" lower="0.0" upper="1.308996939" velocity="5"/>
    <!-- effort="100" velocity="5" -->
  </joint>
  <link name="right_ring_medial_link">
    <inertial>
      <origin rpy="0 0 0" xyz="5.7271879 -1.6164173 -1.1567914"/>
      <mass value="0.027110192"/>
      <inertia ixx="2.2900229e-06" ixy="4.0604622e-07" ixz="1.4362094e-07" iyy="4.2155489e-06" iyz="-4.3115648e-08" izz="4.4292927e-06"/>
    </inertial>
    <visual>
      <origin rpy="0 0 0" xyz="0 0 0"/>
      <geometry>
        <mesh filename="package://dlr_description/meshes/hit2/medial.stl"/>
      </geometry>
      <material name="DLR/LightGrey"/>
    </visual>
    <collision>
      <origin rpy="0 0 0" xyz="0 0 0"/>
      <geometry>
        <mesh filename="package://dlr_description/meshes/hit2/medial.stl"/>
      </geometry>
    </collision>
  </link>
  <joint name="right_ring_outer2_joint" type="revolute">
    <origin rpy="0 0 -1.57079632679" xyz="0.025 0 0"/>
    <parent link="right_ring_medial_link"/>
    <child link="right_ring_distal_link"/>
    <axis xyz="0 0 1"/>
    <dynamics damping="1"/>
    <limit effort="100" lower="0.0" upper="1.308996939" velocity="5"/>
    <!-- effort="100" velocity="5" -->
  </joint>
  <link name="right_ring_distal_link">
    <inertial>
      <origin rpy="0 0 0" xyz="-0.83348211 6.1007977 1.7728256"/>
      <mass value="0.018179709"/>
      <inertia ixx="2.5867271e-06" ixy="1.5840536e-07" ixz="-7.8205885e-10" iyy="8.4596248e-07" iyz="-4.8358115e-09" izz="2.5838485e-06"/>
    </inertial>
    <visual>
      <origin rpy="0 0 0" xyz="0 0 0"/>
      <geometry>
        <mesh filename="package://dlr_description/meshes/hit2/distal.stl"/>
      </geometry>
      <material name="DLR/LightGrey"/>
    </visual>
    <collision>
      <origin rpy="0 0 0" xyz="0 0 0"/>
      <geometry>
        <mesh filename="package://dlr_description/meshes/hit2/distal.stl"/>
      </geometry>
    </collision>
  </link>
  <joint name="right_pinky_abd_joint" type="revolute">
    <origin rpy="-2.96706 -1.57079632679 0" xyz="0.000971571 -0.043396306 0.095043545"/>
    <parent link="right_palm_link"/>
    <child link="right_pinky_abd_link"/>
    <axis xyz="0 0 1"/>
    <dynamics damping="1"/>
    <limit effort="100" lower="-0.349065850399" upper="0.349065850399" velocity="5"/>
    <!-- effort="100" velocity="5" -->
  </joint>
  <link name="right_pinky_abd_link">
    <inertial>
      <origin rpy="0 0 0" xyz="0 0 0"/>
      <mass value="0.0"/>
      <inertia ixx="0" ixy="0" ixz="0" iyy="0" iyz="0" izz="0"/>
    </inertial>
    <!-- possibly add basecover.stl as both geometry and collision... -->
    <visual>
      <origin rpy="0 0 0" xyz="0 0 0"/>
      <geometry>
        <mesh filename="package://dlr_description/meshes/hit2/base.stl"/>
      </geometry>
      <material name="DLR/LightGrey"/>
    </visual>
  </link>
  <joint name="right_pinky_inner_joint" type="revolute">
    <!-- coincident with abd_joint, rotated of 90 degrees along x -->
    <origin rpy="1.57079632679 0 0" xyz="0 0 0"/>
    <parent link="right_pinky_abd_link"/>
    <child link="right_pinky_proximal_link"/>
    <axis xyz="0 0 1"/>
    <dynamics damping="1"/>
    <limit effort="100" lower="0.0" upper="1.308996939" velocity="5"/>
    <!-- effort="100" velocity="5" -->
  </joint>
  <link name="right_pinky_proximal_link">
    <!-- <inertial>
      <origin rpy="0 0 0" xyz="30.164510e -1.0130813 0.50813186"/>
      <mass value="0.044370598"/>
      <inertia ixx="4.5592704e-06" ixy="9.0783105e-07" ixz="-9.399771e-07" iyy="4.9045259e-05" iyz="1.7052714e-08" izz="5.0524234e-05"/>
    </inertial> -->
    <visual>
      <origin rpy="0 0 0" xyz="0 0 0"/>
      <geometry>
        <mesh filename="package://dlr_description/meshes/hit2/proximal.stl"/>
      </geometry>
      <material name="DLR/LightGrey"/>
    </visual>
    <collision>
      <origin rpy="0 0 0" xyz="0 0 0"/>
      <geometry>
        <mesh filename="package://dlr_description/meshes/hit2/proximal.stl"/>
      </geometry>
    </collision>
  </link>
  <joint name="right_pinky_outer1_joint" type="revolute">
    <origin rpy="0 0 0" xyz="0.055 0 0"/>
    <parent link="right_pinky_proximal_link"/>
    <child link="right_pinky_medial_link"/>
    <axis xyz="0 0 1"/>
    <dynamics damping="1"/>
    <limit effort="100" lower="0.0" upper="1.308996939" velocity="5"/>
    <!-- effort="100" velocity="5" -->
  </joint>
  <link name="right_pinky_medial_link">
    <inertial>
      <origin rpy="0 0 0" xyz="5.7271879 -1.6164173 -1.1567914"/>
      <mass value="0.027110192"/>
      <inertia ixx="2.2900229e-06" ixy="4.0604622e-07" ixz="1.4362094e-07" iyy="4.2155489e-06" iyz="-4.3115648e-08" izz="4.4292927e-06"/>
    </inertial>
    <visual>
      <origin rpy="0 0 0" xyz="0 0 0"/>
      <geometry>
        <mesh filename="package://dlr_description/meshes/hit2/medial.stl"/>
      </geometry>
      <material name="DLR/LightGrey"/>
    </visual>
    <collision>
      <origin rpy="0 0 0" xyz="0 0 0"/>
      <geometry>
        <mesh filename="package://dlr_description/meshes/hit2/medial.stl"/>
      </geometry>
    </collision>
  </link>
  <joint name="right_pinky_outer2_joint" type="revolute">
    <origin rpy="0 0 -1.57079632679" xyz="0.025 0 0"/>
    <parent link="right_pinky_medial_link"/>
    <child link="right_pinky_distal_link"/>
    <axis xyz="0 0 1"/>
    <dynamics damping="1"/>
    <limit effort="100" lower="0.0" upper="1.308996939" velocity="5"/>
    <!-- effort="100" velocity="5" -->
  </joint>
  <link name="right_pinky_distal_link">
    <inertial>
      <origin rpy="0 0 0" xyz="-0.83348211 6.1007977 1.7728256"/>
      <mass value="0.018179709"/>
      <inertia ixx="2.5867271e-06" ixy="1.5840536e-07" ixz="-7.8205885e-10" iyy="8.4596248e-07" iyz="-4.8358115e-09" izz="2.5838485e-06"/>
    </inertial>
    <visual>
      <origin rpy="0 0 0" xyz="0 0 0"/>
      <geometry>
        <mesh filename="package://dlr_description/meshes/hit2/distal.stl"/>
      </geometry>
      <material name="DLR/LightGrey"/>
    </visual>
    <collision>
      <origin rpy="0 0 0" xyz="0 0 0"/>
      <geometry>
        <mesh filename="package://dlr_description/meshes/hit2/distal.stl"/>
      </geometry>
    </collision>
  </link>
  <transmission name="thumb_abd_trans" type="pr2_mechanism_model/SimpleTransmission">
    <actuator name="thumb_abd_motor"/>
    <joint name="thumb_abd_joint"/>
    <mechanicalReduction>1</mechanicalReduction>
  </transmission>
  <transmission name="thumb_inner_trans" type="pr2_mechanism_model/SimpleTransmission">
    <actuator name="thumb_inner_motor"/>
    <joint name="thumb_inner_joint"/>
    <mechanicalReduction>1</mechanicalReduction>
  </transmission>
  <transmission name="thumb_outer1_trans" type="pr2_mechanism_model/SimpleTransmission">
    <actuator name="thumb_outer1_motor"/>
    <joint name="thumb_outer1_joint"/>
    <mechanicalReduction>1</mechanicalReduction>
  </transmission>
  <transmission name="thumb_outer2_trans" type="pr2_mechanism_model/SimpleTransmission">
    <actuator name="thumb_outer2_motor"/>
    <joint name="thumb_outer2_joint"/>
    <mechanicalReduction>1</mechanicalReduction>
  </transmission>
  <transmission name="index_abd_trans" type="pr2_mechanism_model/SimpleTransmission">
    <actuator name="index_abd_motor"/>
    <joint name="index_abd_joint"/>
    <mechanicalReduction>1</mechanicalReduction>
  </transmission>
  <transmission name="index_inner_trans" type="pr2_mechanism_model/SimpleTransmission">
    <actuator name="index_inner_motor"/>
    <joint name="index_inner_joint"/>
    <mechanicalReduction>1</mechanicalReduction>
  </transmission>
  <transmission name="index_outer1_trans" type="pr2_mechanism_model/SimpleTransmission">
    <actuator name="index_outer1_motor"/>
    <joint name="index_outer1_joint"/>
    <mechanicalReduction>1</mechanicalReduction>
  </transmission>
  <transmission name="index_outer2_trans" type="pr2_mechanism_model/SimpleTransmission">
    <actuator name="index_outer2_motor"/>
    <joint name="index_outer2_joint"/>
    <mechanicalReduction>1</mechanicalReduction>
  </transmission>
  <transmission name="middle_abd_trans" type="pr2_mechanism_model/SimpleTransmission">
    <actuator name="middle_abd_motor"/>
    <joint name="middle_abd_joint"/>
    <mechanicalReduction>1</mechanicalReduction>
  </transmission>
  <transmission name="middle_inner_trans" type="pr2_mechanism_model/SimpleTransmission">
    <actuator name="middle_inner_motor"/>
    <joint name="middle_inner_joint"/>
    <mechanicalReduction>1</mechanicalReduction>
  </transmission>
  <transmission name="middle_outer1_trans" type="pr2_mechanism_model/SimpleTransmission">
    <actuator name="middle_outer1_motor"/>
    <joint name="middle_outer1_joint"/>
    <mechanicalReduction>1</mechanicalReduction>
  </transmission>
  <transmission name="middle_outer2_trans" type="pr2_mechanism_model/SimpleTransmission">
    <actuator name="middle_outer2_motor"/>
    <joint name="middle_outer2_joint"/>
    <mechanicalReduction>1</mechanicalReduction>
  </transmission>
  <transmission name="ring_abd_trans" type="pr2_mechanism_model/SimpleTransmission">
    <actuator name="ring_abd_motor"/>
    <joint name="ring_abd_joint"/>
    <mechanicalReduction>1</mechanicalReduction>
  </transmission>
  <transmission name="ring_inner_trans" type="pr2_mechanism_model/SimpleTransmission">
    <actuator name="ring_inner_motor"/>
    <joint name="ring_inner_joint"/>
    <mechanicalReduction>1</mechanicalReduction>
  </transmission>
  <transmission name="ring_outer1_trans" type="pr2_mechanism_model/SimpleTransmission">
    <actuator name="ring_outer1_motor"/>
    <joint name="ring_outer1_joint"/>
    <mechanicalReduction>1</mechanicalReduction>
  </transmission>
  <transmission name="ring_outer2_trans" type="pr2_mechanism_model/SimpleTransmission">
    <actuator name="ring_outer2_motor"/>
    <joint name="ring_outer2_joint"/>
    <mechanicalReduction>1</mechanicalReduction>
  </transmission>
  <transmission name="pinky_abd_trans" type="pr2_mechanism_model/SimpleTransmission">
    <actuator name="pinky_abd_motor"/>
    <joint name="pinky_abd_joint"/>
    <mechanicalReduction>1</mechanicalReduction>
  </transmission>
  <transmission name="pinky_inner_trans" type="pr2_mechanism_model/SimpleTransmission">
    <actuator name="pinky_inner_motor"/>
    <joint name="pinky_inner_joint"/>
    <mechanicalReduction>1</mechanicalReduction>
  </transmission>
  <transmission name="pinky_outer1_trans" type="pr2_mechanism_model/SimpleTransmission">
    <actuator name="pinky_outer1_motor"/>
    <joint name="pinky_outer1_joint"/>
    <mechanicalReduction>1</mechanicalReduction>
  </transmission>
  <transmission name="pinky_outer2_trans" type="pr2_mechanism_model/SimpleTransmission">
    <actuator name="pinky_outer2_motor"/>
    <joint name="pinky_outer2_joint"/>
    <mechanicalReduction>1</mechanicalReduction>
  </transmission>
</robot>

